<?xml version="1.0" encoding="utf-8"?>
<!-- =================================================================================== -->
<!-- |    This document was autogenerated by xacro from my_spot.xacro                    | -->
<!-- |    EDITING THIS FILE BY HAND IS NOT RECOMMENDED                                 | -->
<!-- =================================================================================== -->
<!--
THESE COMMANDS AUTO-GENERATE THE NECESSARY *.urdf / *.xml
rosrun xacro xacro -o my_spot.urdf my_spot.xacro
rosrun xacro xacro -o my_spot.xml my_spot.xacro
-->
<!-- Revolute-Revolute Manipulator -->
<robot name="my_spot">
  <!-- Constants for robot dimensions -->
  <!-- Square dimensions (widthxwidth) of beams -->
  <!-- Square dimensions (widthxwidth) of beams -->
  <!-- Square dimensions (widthxwidth) of beams -->
  <!-- Square dimensions (widthxwidth) of beams -->
  <!-- ros_control plugin -->
  <gazebo>
    <plugin filename="libgazebo_ros_control.so" name="gazebo_ros_control">
      <robotNamespace>/my_spot</robotNamespace>
      <robotSimType>gazebo_ros_control/DefaultRobotHWSim</robotSimType>
    </plugin>
  </gazebo>
  <gazebo reference="left_limb">
    <material>Gazebo/Black</material>
  </gazebo>
  <gazebo reference="right_limb">
    <mu1 value="1.0"/>
    <mu2 value="1.0"/>
    <kp value="10000000.0"/>
    <kd value="1.0"/>
    <fdir1 value="1 0 0"/>
    <material>Gazebo/Black</material>
  </gazebo>
  <!-- link1_torso -->
  <gazebo reference="link1_torso">
    <material>Gazebo/Orange</material>
  </gazebo>
  <gazebo reference="left_latissimus_dorsi">
    <material>Gazebo/Orange</material>
  </gazebo>
  <gazebo reference="right_latissimus_dorsi">
    <material>Gazebo/Orange</material>
  </gazebo>
  <!-- Link2 -->
  <gazebo reference="link2">
    <mu1>0.2</mu1>
    <mu2>0.2</mu2>
    <material>Gazebo/Black</material>
  </gazebo>
  <!-- Link3_inner -->
  <gazebo reference="link3_inner">
    <mu1>0.2</mu1>
    <mu2>0.2</mu2>
    <material>Gazebo/White</material>
  </gazebo>
  <!-- Link3_inner_brace -->
  <gazebo reference="link3_inner_brace">
    <mu1>0.2</mu1>
    <mu2>0.2</mu2>
    <material>Gazebo/White</material>
  </gazebo>
  <!-- Link3 -->
  <gazebo reference="link3_middle">
    <mu1>0.2</mu1>
    <mu2>0.2</mu2>
    <material>Gazebo/Orange</material>
  </gazebo>
  <!-- Link3_outer -->
  <gazebo reference="link3_outer">
    <mu1>0.2</mu1>
    <mu2>0.2</mu2>
    <material>Gazebo/Green</material>
  </gazebo>
  <!-- Link3_outer_brace -->
  <gazebo reference="link3_outer_brace">
    <mu1>0.2</mu1>
    <mu2>0.2</mu2>
    <material>Gazebo/Green</material>
  </gazebo>
  <!-- Link3_outer_x -->
  <gazebo reference="link3_outer_x">
    <mu1>0.2</mu1>
    <mu2>0.2</mu2>
    <material>Gazebo/Green</material>
  </gazebo>
  <!-- Link4 -->
  <gazebo reference="link4">
    <mu1>0.2</mu1>
    <mu2>0.2</mu2>
    <material>Gazebo/Blue</material>
  </gazebo>
  <!-- camera_link -->
  <gazebo reference="camera_link">
    <mu1>0.2</mu1>
    <mu2>0.2</mu2>
    <material>Gazebo/Red</material>
  </gazebo>
  <!-- hokuyo -->
  <gazebo reference="hokuyo_link">
    <sensor name="head_hokuyo_sensor" type="gpu_ray">
      <pose>0 0 0 0 0 0</pose>
      <visualize>false</visualize>
      <update_rate>40</update_rate>
      <ray>
        <scan>
          <horizontal>
            <samples>720</samples>
            <resolution>1</resolution>
            <min_angle>-1.570796</min_angle>
            <max_angle>1.570796</max_angle>
          </horizontal>
        </scan>
        <range>
          <min>0.10</min>
          <max>30.0</max>
          <resolution>0.01</resolution>
        </range>
        <noise>
          <type>gaussian</type>
          <!-- Noise parameters based on published spec for Hokuyo laser
               achieving "+-30mm" accuracy at range < 10m.  A mean of 0.0m and
               stddev of 0.01m will put 99.7% of samples within 0.03m of the true
               reading. -->
          <mean>0.0</mean>
          <stddev>0.01</stddev>
        </noise>
      </ray>
      <plugin filename="libgazebo_ros_gpu_laser.so" name="gazebo_ros_head_hokuyo_controller">
        <topicName>/my_spot/laser/scan</topicName>
        <frameName>hokuyo_link</frameName>
      </plugin>
    </sensor>
  </gazebo>
  <!-- camera -->
  <gazebo reference="camera_link">
    <sensor name="camera1" type="camera">
      <update_rate>30.0</update_rate>
      <camera name="head">
        <horizontal_fov>1.3962634</horizontal_fov>
        <image>
          <width>800</width>
          <height>800</height>
          <format>R8G8B8</format>
        </image>
        <clip>
          <near>0.02</near>
          <far>300</far>
        </clip>
        <noise>
          <type>gaussian</type>
          <!-- Noise is sampled independently per pixel on each frame.
               That pixel's noise value is added to each of its color
               channels, which at that point lie in the range [0,1]. -->
          <mean>0.0</mean>
          <stddev>0.007</stddev>
        </noise>
      </camera>
      <plugin filename="libgazebo_ros_camera.so" name="camera_controller">
        <alwaysOn>true</alwaysOn>
        <updateRate>0.0</updateRate>
        <cameraName>my_spot/camera1</cameraName>
        <imageTopicName>image_raw</imageTopicName>
        <cameraInfoTopicName>camera_info</cameraInfoTopicName>
        <frameName>camera_link_optical</frameName>
        <!-- setting hackBaseline to anything but 0.0 will cause a misalignment
            between the gazebo sensor image and the frame it is supposed to
            be attached to -->
        <hackBaseline>0.0</hackBaseline>
        <distortionK1>0.0</distortionK1>
        <distortionK2>0.0</distortionK2>
        <distortionK3>0.0</distortionK3>
        <distortionT1>0.0</distortionT1>
        <distortionT2>0.0</distortionT2>
        <CxPrime>0</CxPrime>
        <Cx>0.0</Cx>
        <Cy>0.0</Cy>
        <focalLength>0.0</focalLength>
      </plugin>
    </sensor>
  </gazebo>
  <material name="black">
    <color rgba="0.0 0.0 0.0 1.0"/>
  </material>
  <material name="blue">
    <color rgba="0.0 0.0 0.8 1.0"/>
  </material>
  <material name="green">
    <color rgba="0.0 0.8 0.0 1.0"/>
  </material>
  <material name="grey">
    <color rgba="0.2 0.2 0.2 1.0"/>
  </material>
  <material name="orange">
    <color rgba="1.0 0.423529411765 0.0392156862745 1.0"/>
  </material>
  <material name="brown">
    <color rgba="0.870588235294 0.811764705882 0.764705882353 1.0"/>
  </material>
  <material name="red">
    <color rgba="0.8 0.0 0.0 1.0"/>
  </material>
  <material name="white">
    <color rgba="1.0 1.0 1.0 1.0"/>
  </material>
  <!-- Used for fixing robot to Gazebo 'base_link' -->
  <link name="world"/>
  <joint name="fixed" type="fixed">
    <parent link="world"/>
    <child link="link1_torso"/>
    <origin rpy="0 0 0" xyz="0 0 2"/>
  </joint>
  <!--leg lr="left" tX="-2"/-->
  <!-- Middle Link -->
  <link name="left_limb">
    <collision>
      <origin rpy="0 0 0" xyz="0 -0.06 0.0"/>
      <geometry>
        <box size="0.12 0.24 0.12"/>
      </geometry>
    </collision>
    <visual>
      <origin rpy="0 0 0" xyz="0 -0.06 0.0"/>
      <geometry>
        <box size="0.12 0.24 0.12"/>
      </geometry>
      <material name="black"/>
    </visual>
    <inertial>
      <origin rpy="0 0 0" xyz="0 -0.06 0.0"/>
      <mass value="1"/>
      <inertia ixx="0.006" ixy="0.0" ixz="0.0" iyy="0.0024" iyz="0.0" izz="0.006"/>
    </inertial>
  </link>
  <!-- Middle Link -->
  <link name="right_limb">
    <collision>
      <origin rpy="0 0 0" xyz="2 0.06 0.0"/>
      <geometry>
        <box size="0.12 0.24 0.12"/>
      </geometry>
    </collision>
    <visual>
      <origin rpy="0 0 0" xyz="2 0.06 0.0"/>
      <geometry>
        <box size="0.12 0.24 0.12"/>
      </geometry>
      <material name="black"/>
    </visual>
    <inertial>
      <origin rpy="0 0 0" xyz="2 0.06 0.0"/>
      <mass value="1"/>
      <inertia ixx="0.006" ixy="0.0" ixz="0.0" iyy="0.0024" iyz="0.0" izz="0.006"/>
    </inertial>
  </link>
  <!-- Base Link -->
  <link name="link1_torso">
    <collision>
      <origin rpy="0 0 0" xyz="0 0 0.06"/>
      <geometry>
        <box size="2.4 0.48 0.12"/>
      </geometry>
    </collision>
    <visual>
      <origin rpy="0 0 0" xyz="0 0 0.06"/>
      <geometry>
        <box size="2.4 0.48 0.12"/>
      </geometry>
      <material name="orange"/>
    </visual>
    <inertial>
      <origin rpy="0 0 0" xyz="0 0 0.06"/>
      <mass value="1"/>
      <inertia ixx="0.0204" ixy="0.0" ixz="0.0" iyy="0.4812" iyz="0.0" izz="0.4992"/>
    </inertial>
  </link>
  <link name="left_latissimus_dorsi">
    <collision>
      <origin rpy="0 0 0" xyz="0 0 0"/>
      <geometry>
        <box size="2.16 0.12 0.12"/>
      </geometry>
    </collision>
    <visual>
      <origin rpy="0 0 0" xyz="0 0 0"/>
      <geometry>
        <box size="2.16 0.12 0.12"/>
      </geometry>
      <material name="orange"/>
    </visual>
    <inertial>
      <origin rpy="0 0 0" xyz="0 0 0"/>
      <mass value="1"/>
      <inertia ixx="0.0204" ixy="0.0" ixz="0.0" iyy="0.4812" iyz="0.0" izz="0.4992"/>
    </inertial>
  </link>
  <link name="right_latissimus_dorsi">
    <collision>
      <origin rpy="0 0 0" xyz="0 0 0"/>
      <geometry>
        <box size="2.16 0.12 0.12"/>
      </geometry>
    </collision>
    <visual>
      <origin rpy="0 0 0" xyz="0 0 0"/>
      <geometry>
        <box size="2.16 0.12 0.12"/>
      </geometry>
      <material name="orange"/>
    </visual>
    <inertial>
      <origin rpy="0 0 0" xyz="0 0 0"/>
      <mass value="1"/>
      <inertia ixx="0.0204" ixy="0.0" ixz="0.0" iyy="0.4812" iyz="0.0" izz="0.4992"/>
    </inertial>
  </link>
  <joint name="joint_left_latissimus_dorsi" type="fixed">
    <parent link="link1_torso"/>
    <child link="left_latissimus_dorsi"/>
    <origin rpy="0 0 0" xyz="0 0.3 0.06"/>
    <axis xyz="1 0 0"/>
    <!-- ___________________________________AXIS -->
  </joint>
  <joint name="joint_right_latissimus_dorsi" type="fixed">
    <parent link="link1_torso"/>
    <child link="right_latissimus_dorsi"/>
    <origin rpy="0 0 0" xyz="0 -0.3 0.06"/>
    <axis xyz="1 0 0"/>
    <!-- ___________________________________AXIS -->
  </joint>
  <joint name="joint1" type="continuous">
    <parent link="link1_torso"/>
    <child link="link2"/>
    <origin rpy="0 0 0" xyz="1.14 0.3 0.06"/>
    <!--origin xyz="0 ${y_width_body/2 + axel_offset*2} ${z_width_body - axel_offset }" rpy="0 0 0"/-->
    <!--origin xyz="0 ${width} ${height1 - axel_offset}" rpy="0 0 0"/-->
    <axis xyz="1 0 0"/>
    <!-- ___________________________________AXIS -->
    <dynamics damping="0.7" friction="1"/>
  </joint>
  <!-- Middle Link -->
  <link name="link2">
    <collision>
      <origin rpy="0 0 0" xyz="0 0.06 0.0"/>
      <geometry>
        <box size="0.12 0.24 0.12"/>
      </geometry>
    </collision>
    <visual>
      <origin rpy="0 0 0" xyz="0 0.06 0.0"/>
      <geometry>
        <box size="0.12 0.24 0.12"/>
      </geometry>
      <material name="black"/>
    </visual>
    <inertial>
      <origin rpy="0 0 0" xyz="0 0.06 0.0"/>
      <mass value="1"/>
      <inertia ixx="0.006" ixy="0.0" ixz="0.0" iyy="0.0024" iyz="0.0" izz="0.006"/>
    </inertial>
  </link>
  <joint name="joint2" type="continuous">
    <parent link="link2"/>
    <child link="link3_middle"/>
    <origin rpy="0 0 0" xyz="0 0.18 0"/>
    <!--origin xyz="${x_width_upperarm_left+axel_offset_small*3} ${y_width_shoulder_left/2+axel_offset_small*3 } 0" rpy="0 0 0"/-->
    <!--origin xyz="${-x_width_upperarm_left/2+axel_offset_small*3} ${y_width_shoulder_left/2+axel_offset_small*3 } 0" rpy="0 0 0"/-->
    <!--origin xyz="0 ${-y_width_shoulder_left - axel_offset_small } ${z_width_shoulder_left - axel_offset_small*2}" rpy="0 0 0"/-->
    <axis xyz="0 1 0"/>
    <!-- ___________________________________AXIS -->
    <dynamics damping="0.7"/>
  </joint>
  <!-- UPPERARM Link inner- ->-->
  <link name="link3_inner">
    <collision>
      <origin rpy="0 0 0" xyz="0 0 0"/>
      <geometry>
        <box size="1.2 0.04 0.12"/>
      </geometry>
    </collision>
    <visual>
      <origin rpy="0 0 0" xyz="0 0 0"/>
      <geometry>
        <box size="1.2 0.04 0.12"/>
      </geometry>
      <material name="white"/>
    </visual>
    <inertial>
      <origin rpy="0 0 0" xyz="0 0 0"/>
      <mass value="1"/>
      <inertia ixx="0.00133333333333" ixy="0.0" ixz="0.0" iyy="0.1212" iyz="0.0" izz="0.120133333333"/>
    </inertial>
  </link>
  <joint name="joint3_inner" type="fixed">
    <parent link="link3_middle"/>
    <child link="link3_inner"/>
    <origin rpy="0 0 0" xyz="-0.54 0.02 0"/>
    <axis xyz="0 1 0"/>
    <!-- ___________________________________AXIS -->
    <dynamics damping="0.7"/>
  </joint>
  <!-- UPPERARM Link inner BRACE-->
  <link name="link3_inner_brace">
    <collision>
      <origin rpy="0 0 0" xyz="0 0 0"/>
      <geometry>
        <box size="0.12 0.04 0.12"/>
      </geometry>
    </collision>
    <visual>
      <origin rpy="0 0 0" xyz="0 0 0"/>
      <geometry>
        <box size="0.12 0.04 0.12"/>
      </geometry>
      <material name="white"/>
    </visual>
    <inertial>
      <origin rpy="0 0 0" xyz="0 0 0"/>
      <mass value="1"/>
      <inertia ixx="0.00133333333333" ixy="0.0" ixz="0.0" iyy="0.1212" iyz="0.0" izz="0.120133333333"/>
    </inertial>
  </link>
  <joint name="joint3_inner_brace" type="fixed">
    <parent link="link3_inner"/>
    <child link="link3_inner_brace"/>
    <origin rpy="0 0 0" xyz="-0.54 0 -0.12"/>
    <axis xyz="0 1 0"/>
    <dynamics damping="0.7"/>
  </joint>
  <!-- UPPERARM Link middle-->
  <link name="link3_middle">
    <collision>
      <origin rpy="0 0 0" xyz="-0.36 0.06 0"/>
      <geometry>
        <box size="0.84 0.04 0.12"/>
      </geometry>
    </collision>
    <visual>
      <origin rpy="0 0 0" xyz="-0.36 0.06 0"/>
      <geometry>
        <box size="0.84 0.04 0.12"/>
      </geometry>
      <material name="orange"/>
    </visual>
    <inertial>
      <origin rpy="0 0 0" xyz="-0.24 0.06 0"/>
      <mass value="1"/>
      <inertia ixx="0.00133333333333" ixy="0.0" ixz="0.0" iyy="0.1212" iyz="0.0" izz="0.120133333333"/>
      <!--inertia
	  ixx="${mass / 12.0 * (width*width + height3*height3)}" ixy="0.0" ixz="0.0"
	  iyy="${mass / 12.0 * (height3*height3 + width*width)}" iyz="0.0"
	  izz="${mass / 12.0 * (width*width + width*width)}"/-->
    </inertial>
  </link>
  <!-- UPPERARM Link outer-->
  <link name="link3_outer">
    <collision>
      <origin rpy="0 0 0" xyz="0 0 0"/>
      <geometry>
        <box size="1.2 0.04 0.12"/>
      </geometry>
    </collision>
    <visual>
      <origin rpy="0 0 0" xyz="0 0 0"/>
      <geometry>
        <box size="1.2 0.04 0.12"/>
      </geometry>
      <material name="green"/>
    </visual>
    <inertial>
      <origin rpy="0 0 0" xyz="0 0 0"/>
      <mass value="1"/>
      <inertia ixx="0.00133333333333" ixy="0.0" ixz="0.0" iyy="0.1212" iyz="0.0" izz="0.120133333333"/>
    </inertial>
  </link>
  <joint name="joint3_outer" type="fixed">
    <parent link="link3_middle"/>
    <child link="link3_outer"/>
    <origin rpy="0 0 0" xyz="-0.54 0.1 0"/>
    <axis xyz="0 1 0"/>
    <dynamics damping="0.7"/>
  </joint>
  <!-- UPPERARM Link outer BRACE-->
  <link name="link3_outer_brace">
    <collision>
      <origin rpy="0 0 0" xyz="0 0 0"/>
      <geometry>
        <box size="0.12 0.04 0.12"/>
      </geometry>
    </collision>
    <visual>
      <origin rpy="0 0 0" xyz="0 0 0"/>
      <geometry>
        <box size="0.12 0.04 0.12"/>
      </geometry>
      <material name="green"/>
    </visual>
    <inertial>
      <origin rpy="0 0 0" xyz="0 0 0"/>
      <mass value="1"/>
      <inertia ixx="0.00133333333333" ixy="0.0" ixz="0.0" iyy="0.1212" iyz="0.0" izz="0.120133333333"/>
    </inertial>
  </link>
  <joint name="joint3_outer_brace" type="fixed">
    <parent link="link3_outer"/>
    <child link="link3_outer_brace"/>
    <origin rpy="0 0 0" xyz="-0.54 0 -0.12"/>
    <axis xyz="0 1 0"/>
    <dynamics damping="0.7"/>
  </joint>
  <!-- UPPERARM Link outer x-->
  <link name="link3_outer_x">
    <collision>
      <origin rpy="0 0 0" xyz="0 0 0"/>
      <geometry>
        <box size="0.12 0.04 0.12"/>
      </geometry>
    </collision>
    <visual>
      <origin rpy="0 0 0" xyz="0 0 0"/>
      <geometry>
        <box size="0.12 0.04 0.12"/>
      </geometry>
      <material name="green"/>
    </visual>
    <inertial>
      <origin rpy="0 0 0" xyz="0 0 0"/>
      <mass value="1"/>
      <inertia ixx="0.00133333333333" ixy="0.0" ixz="0.0" iyy="0.1212" iyz="0.0" izz="0.120133333333"/>
    </inertial>
  </link>
  <joint name="joint3_outer_x" type="fixed">
    <parent link="link3_outer"/>
    <child link="link3_outer_x"/>
    <origin rpy="0 0 0" xyz="-0.54 0 0.12"/>
    <axis xyz="0 1 0"/>
    <dynamics damping="0.7"/>
  </joint>
  <!-- FOREARM Link -->
  <link name="link4">
    <collision>
      <origin rpy="0 0 0" xyz="0.42 0 0.0"/>
      <geometry>
        <box size="1.44 0.04 0.12"/>
      </geometry>
    </collision>
    <visual>
      <origin rpy="0 0 0" xyz="0.42 0 0.0"/>
      <geometry>
        <box size="1.44 0.04 0.12"/>
      </geometry>
      <material name="blue"/>
    </visual>
    <inertial>
      <origin rpy="0 0 0" xyz="0.42 0 0.0"/>
      <mass value="1"/>
      <inertia ixx="0.00133333333333" ixy="0.0" ixz="0.0" iyy="0.1212" iyz="0.0" izz="0.120133333333"/>
      <!--inertia
	  ixx="${mass / 12.0 * (width*width + height3*height3)}" ixy="0.0" ixz="0.0"
	  iyy="${mass / 12.0 * (height3*height3 + width*width)}" iyz="0.0"
	  izz="${mass / 12.0 * (width*width + width*width)}"/-->
    </inertial>
  </link>
  <joint name="joint_last" type="continuous">
    <parent link="link3_middle"/>
    <child link="link4"/>
    <origin rpy="0 0 0" xyz="-1.08 0.06 -0.12"/>
    <axis xyz="0 1 0"/>
    <!-- ___________________________________AXIS -->
    <dynamics damping="0.7"/>
  </joint>
  <joint name="hokuyo_joint" type="fixed">
    <axis xyz="0 1 0"/>
    <origin rpy="0 0 0" xyz="0 0 0.09"/>
    <parent link="link1_torso"/>
    <child link="hokuyo_link"/>
  </joint>
  <!-- Hokuyo Laser -->
  <link name="hokuyo_link">
    <collision>
      <origin rpy="0 0 0" xyz="0 0 0"/>
      <geometry>
        <box size="0.1 0.1 0.1"/>
      </geometry>
    </collision>
    <visual>
      <origin rpy="0 0 0" xyz="0 0 0"/>
      <geometry>
        <mesh filename="package://my_spot_description/meshes/hokuyo.dae"/>
      </geometry>
    </visual>
    <inertial>
      <mass value="1e-5"/>
      <origin rpy="0 0 0" xyz="0 0 0"/>
      <inertia ixx="1e-6" ixy="0" ixz="0" iyy="1e-6" iyz="0" izz="1e-6"/>
    </inertial>
  </link>
  <joint name="camera_joint" type="fixed">
    <axis xyz="0 1 0"/>
    <origin rpy="0 0 0" xyz="0.05 0 1.08"/>
    <parent link="link1_torso"/>
    <child link="camera_link"/>
  </joint>
  <!-- Camera -->
  <link name="camera_link">
    <collision>
      <origin rpy="0 0 0" xyz="0 0 0"/>
      <geometry>
        <box size="0.05 0.05 0.05"/>
      </geometry>
    </collision>
    <visual>
      <origin rpy="0 0 0" xyz="0 0 0"/>
      <geometry>
        <box size="0.05 0.05 0.05"/>
      </geometry>
      <material name="red"/>
    </visual>
    <inertial>
      <mass value="1e-5"/>
      <origin rpy="0 0 0" xyz="0 0 0"/>
      <inertia ixx="1e-6" ixy="0" ixz="0" iyy="1e-6" iyz="0" izz="1e-6"/>
    </inertial>
  </link>
  <!-- generate an optical frame http://www.ros.org/reps/rep-0103.html#suffix-frames
      so that ros and opencv can operate on the camera frame correctly -->
  <joint name="camera_optical_joint" type="fixed">
    <!-- these values have to be these values otherwise the gazebo camera image
        won't be aligned properly with the frame it is supposedly originating from -->
    <origin rpy="-1.57079632679 0 -1.57079632679" xyz="0 0 0"/>
    <parent link="camera_link"/>
    <child link="camera_link_optical"/>
  </joint>
  <link name="camera_link_optical">
  </link>
  <transmission name="tran1">
    <type>transmission_interface/SimpleTransmission</type>
    <joint name="joint1">
      <hardwareInterface>hardware_interface/EffortJointInterface</hardwareInterface>
    </joint>
    <actuator name="motor1">
      <hardwareInterface>hardware_interface/EffortJointInterface</hardwareInterface>
      <mechanicalReduction>1</mechanicalReduction>
    </actuator>
  </transmission>
  <transmission name="tran2">
    <type>transmission_interface/SimpleTransmission</type>
    <joint name="joint2">
      <hardwareInterface>hardware_interface/EffortJointInterface</hardwareInterface>
    </joint>
    <actuator name="motor2">
      <hardwareInterface>hardware_interface/EffortJointInterface</hardwareInterface>
      <mechanicalReduction>1</mechanicalReduction>
    </actuator>
  </transmission>
  <transmission name="tran3">
    <type>transmission_interface/SimpleTransmission</type>
    <joint name="joint_last">
      <hardwareInterface>hardware_interface/EffortJointInterface</hardwareInterface>
    </joint>
    <actuator name="motor3">
      <hardwareInterface>hardware_interface/EffortJointInterface</hardwareInterface>
      <mechanicalReduction>1</mechanicalReduction>
    </actuator>
  </transmission>
  <joint name="joint4" type="continuous">
    <parent link="link1_torso"/>
    <child link="left_limb"/>
    <origin rpy="0 0 0" xyz="0 1 0"/>
    <axis xyz="1 0 0"/>
    <dynamics damping="0.7"/>
  </joint>
  <transmission name="tran_left_limb">
    <type>transmission_interface/SimpleTransmission</type>
    <joint name="joint4">
      <hardwareInterface>hardware_interface/EffortJointInterface</hardwareInterface>
    </joint>
    <actuator name="motor_left_limb">
      <hardwareInterface>hardware_interface/EffortJointInterface</hardwareInterface>
      <mechanicalReduction>1</mechanicalReduction>
    </actuator>
  </transmission>
  <joint name="joint_right_limb" type="continuous">
    <parent link="link1_torso"/>
    <child link="right_limb"/>
    <origin rpy="0 0 0" xyz="0 0 0"/>
    <dynamics damping="0.7"/>
  </joint>
  <transmission name="tran_right_limb">
    <type>transmission_interface/SimpleTransmission</type>
    <joint name="joint_right_limb">
      <hardwareInterface>hardware_interface/EffortJointInterface</hardwareInterface>
    </joint>
    <actuator name="motor_right_limb">
      <hardwareInterface>hardware_interface/EffortJointInterface</hardwareInterface>
      <mechanicalReduction>1</mechanicalReduction>
    </actuator>
  </transmission>
</robot>
